{
  "Closure-14": {
    "prompt": "\nYou need to first analyse the buggy code, trigger test and error message. Then analyse the root cause and finally try to provide a repair suggestions to fix the buggy.\nNote that the bug can be fixed by modifying only the given buggy code; do not attempt to modify the class, add new functions, or conduct further testing.\n\n1. Buggy Function: \n/**\n* Computes the follow() node of a given node and its parent. There is a side\n* effect when calling this function. If this function computed an edge that\n* exists a FINALLY, it'll attempt to connect the fromNode to the outer\n* FINALLY according to the finallyMap.\n*\n* @param fromNode The original source node since {@code node} is changed\n*        during recursion.\n* @param node The node that follow() should compute.\n*/\nprivate static Node computeFollowNode(\n    Node fromNode, Node node, ControlFlowAnalysis cfa) {\n  /*\n   * This is the case where:\n   *\n   * 1. Parent is null implies that we are transferring control to the end of\n   * the script.\n   *\n   * 2. Parent is a function implies that we are transferring control back to\n   * the caller of the function.\n   *\n   * 3. If the node is a return statement, we should also transfer control\n   * back to the caller of the function.\n   *\n   * 4. If the node is root then we have reached the end of what we have been\n   * asked to traverse.\n   *\n   * In all cases we should transfer control to a \"symbolic return\" node.\n   * This will make life easier for DFAs.\n   */\n  Node parent = node.getParent();\n  if (parent == null || parent.isFunction() ||\n      (cfa != null && node == cfa.root)) {\n    return null;\n  }\n\n  // If we are just before a IF/WHILE/DO/FOR:\n  switch (parent.getType()) {\n    // The follow() of any of the path from IF would be what follows IF.\n    case Token.IF:\n      return computeFollowNode(fromNode, parent, cfa);\n    case Token.CASE:\n    case Token.DEFAULT_CASE:\n      // After the body of a CASE, the control goes to the body of the next\n      // case, without having to go to the case condition.\n      if (parent.getNext() != null) {\n        if (parent.getNext().isCase()) {\n          return parent.getNext().getFirstChild().getNext();\n        } else if (parent.getNext().isDefaultCase()) {\n          return parent.getNext().getFirstChild();\n        } else {\n          Preconditions.checkState(false, \"Not reachable\");\n        }\n      } else {\n        return computeFollowNode(fromNode, parent, cfa);\n      }\n      break;\n    case Token.FOR:\n      if (NodeUtil.isForIn(parent)) {\n        return parent;\n      } else {\n        return parent.getFirstChild().getNext().getNext();\n      }\n    case Token.WHILE:\n    case Token.DO:\n      return parent;\n    case Token.TRY:\n      // If we are coming out of the TRY block...\n      if (parent.getFirstChild() == node) {\n        if (NodeUtil.hasFinally(parent)) { // and have FINALLY block.\n          return computeFallThrough(parent.getLastChild());\n        } else { // and have no FINALLY.\n          return computeFollowNode(fromNode, parent, cfa);\n        }\n      // CATCH block.\n      } else if (NodeUtil.getCatchBlock(parent) == node){\n        if (NodeUtil.hasFinally(parent)) { // and have FINALLY block.\n          return computeFallThrough(node.getNext());\n        } else {\n          return computeFollowNode(fromNode, parent, cfa);\n        }\n      // If we are coming out of the FINALLY block...\n      } else if (parent.getLastChild() == node){\n        if (cfa != null) {\n          for (Node finallyNode : cfa.finallyMap.get(parent)) {\n            cfa.createEdge(fromNode, Branch.UNCOND, finallyNode);\n          }\n        }\n        return computeFollowNode(fromNode, parent, cfa);\n      }\n  }\n\n  // Now that we are done with the special cases follow should be its\n  // immediate sibling, unless its sibling is a function\n  Node nextSibling = node.getNext();\n\n  // Skip function declarations because control doesn't get pass into it.\n  while (nextSibling != null && nextSibling.isFunction()) {\n    nextSibling = nextSibling.getNext();\n  }\n\n  if (nextSibling != null) {\n    return computeFallThrough(nextSibling);\n  } else {\n    // If there are no more siblings, control is transferred up the AST.\n    return computeFollowNode(fromNode, parent, cfa);\n  }\n}\n\n2. Trigger Test: \n  public void testIssue779() {\n\n    testNotMissing(\n\n        \"var a = f(); try { alert(); if (a > 0) return 1; }\" +\n\n        \"finally { a = 5; } return 2;\");\n\n  }\n\n\n3. Error Message: \n\tat com.google.javascript.jscomp.CompilerTestCase.test(CompilerTestCase.java:816)  assertEquals(          \"Unexpected error(s): \" + Joiner.on(\"\\n\").join(compiler.getErrors()),          0, compiler.getErrorCount());\n\tat com.google.javascript.jscomp.CompilerTestCase.test(CompilerTestCase.java:445)  test(compiler, new String[] { expected }, error, warning, description);\n\tat com.google.javascript.jscomp.CompilerTestCase.test(CompilerTestCase.java:371)  test(externsInputs, js, expected, error, warning, null);\n\tat com.google.javascript.jscomp.CompilerTestCase.test(CompilerTestCase.java:340)  test(js, expected, error, null);\n\tat com.google.javascript.jscomp.CompilerTestCase.test(CompilerTestCase.java:328)  test(js, expected, (DiagnosticType) null);\n\tat com.google.javascript.jscomp.CompilerTestCase.testSame(CompilerTestCase.java:560)  test(js, js);\n\n\nFirst, analyze the trigger test and error message, and then analyse the root cause of the buggy function in the format 'Root Cause: {content}'. Provide multiple distinct and detailed patch suggestions for resolving this bug.\nYou suggestions should be in the format 'Suggestion 1: {suggestion title}\\n{detailed description}', etc.",
    "solutions": [
      {
        "reasoning_steps": "Step 1: Response\n{\n    \"title\": \"Analyzing Bug Context\",\n    \"content\": \"First, let's understand the buggy function and its intended behavior. The function computeFollowNode is used to compute the follow() node of a given node and its parent. It seems to be part of a control flow analysis in a compiler. The trigger test is a JavaScript code snippet that causes the error. The error message indicates that there is an unexpected error during compilation.\",\n    \"next_action\": \"continue\"\n}\n\n{\n    \"title\": \"Understanding Trigger Test and Error Message\",\n    \"content\": \"The trigger test is a JavaScript code snippet that contains a try-finally block with a return statement inside the try block. The error message indicates that there is an unexpected error during compilation. This suggests that the bug is related to the handling of try-finally blocks and return statements.\",\n    \"next_action\": \"continue\"\n}\n\n{\n    \"title\": \"Analyzing Root Cause\",\n    \"content\": \"Root Cause: The bug is caused by the incorrect handling of try-finally blocks and return statements in the computeFollowNode function. Specifically, when a return statement is encountered inside a try block, the function does not correctly handle the finally block and the return statement. This leads to an unexpected error during compilation.\",\n    \"next_action\": \"continue\"\n}\n\n{\n    \"title\": \"Exploring Potential Fixes\",\n    \"content\": \"To fix this bug, we need to modify the computeFollowNode function to correctly handle try-finally blocks and return statements. Here are a few potential fixes:\",\n    \"next_action\": \"continue\"\n}\n\n{\n    \"title\": \"Suggestion 1: Correctly Handle Return Statements Inside Try Blocks\",\n    \"content\": \"One potential fix is to add a special case to handle return statements inside try blocks. When a return statement is encountered, the function should check if it is inside a try block and if so, it should correctly handle the finally block and the return statement.\",\n    \"next_action\": \"continue\"\n}\n\n{\n    \"title\": \"Suggestion 2: Use a More Robust Algorithm to Handle Control Flow\",\n    \"content\": \"Another potential fix is to use a more robust algorithm to handle control flow in the computeFollowNode function. This could involve using a more sophisticated data structure to represent the control flow graph, or using a more advanced algorithm to analyze the control flow.\",\n    \"next_action\": \"continue\"\n}\n\n{\n    \"title\": \"Suggestion 3: Add Additional Error Checking to Handle Unexpected Cases\",\n    \"content\": \"A third potential fix is to add additional error checking to handle unexpected cases. This could involve adding more checks to ensure that the function is correctly handling try-finally blocks and return statements, and adding more error messages to help diagnose any issues that may arise.\",\n    \"next_action\": \"final_answer\"\n}\n\n{\n    \"title\": \"Final Answer\",\n    \"content\": \"Based on the analysis, the best solution is to implement Suggestion 1: Correctly Handle Return Statements Inside Try Blocks. This involves adding a special case to handle return statements inside try blocks, and correctly handling the finally block and the return statement.\",\n    \"next_action\": \"final_answer\"\n}",
        "final_solution": "Root Cause: The bug is caused by the incorrect handling of try-finally blocks and return statements in the computeFollowNode function. Specifically, when a return statement is encountered inside a try block, the function does not correctly handle the finally block and the return statement. This leads to an unexpected error during compilation.\n\nSuggestion 1: Correctly Handle Return Statements Inside Try Blocks\nTo fix this bug, we need to add a special case to handle return statements inside try blocks. When a return statement is encountered, the function should check if it is inside a try block and if so, it should correctly handle the finally block and the return statement. This can be achieved by adding a conditional statement to check if the current node is a return statement and if its parent is a try block. If both conditions are true, the function should handle the finally block and the return statement accordingly.\n\nSuggestion 2: Modify the Control Flow Analysis to Handle Try-Finally Blocks\nAnother potential fix is to modify the control flow analysis to handle try-finally blocks correctly. This can be achieved by adding a new case to the switch statement to handle try blocks. When a try block is encountered, the function should analyze the control flow inside the try block and handle the finally block accordingly. This can be done by recursively calling the computeFollowNode function on the try block's children.\n\nSuggestion 3: Add a Special Case to Handle Return Statements in Try Blocks with Finally Blocks\nA third potential fix is to add a special case to handle return statements in try blocks with finally blocks. When a return statement is encountered inside a try block with a finally block, the function should handle the finally block and the return statement accordingly. This can be achieved by adding a conditional statement to check if the current node is a return statement and if its parent is a try block with a finally block. If both conditions are true, the function should handle the finally block and the return statement accordingly.",
        "total_time": 7.598264932632446
      }
    ]
  }
}